<?xml version="1.0" encoding="utf-8"?>
<mujoco model="segway">
  <compiler angle="radian" meshdir="meshes"/>
  <option timestep="0.002" gravity="0 0 -9.81" integrator="RK4" iterations="100" cone="pyramidal" jacobian="dense">
    <flag contact="enable"/>
  </option>
  <default>
    <joint damping="0.01"/>
    <geom condim="4" friction="1.0 0.005 0.001" solref="0.004 1" solimp="0.9 0.95 0.001"/>
  </default>
  <asset>
    <mesh name="body_mesh" file="body.stl"/>
    <!-- The L_wheel.stl / R_wheel.stl files were authored at radius
         ~0.192 m, but the segway physics model uses wheel_radius = 0.1 m
         (see params.yaml). Without scaling, the visual wheel extends
         ~9 cm below the floor at rest (collision sphere is at z = 0.1 m,
         but mesh bottom is at z = -0.092 m). Scale 0.52× brings the
         visual radius to 0.1 m so the wheel sits cleanly on the floor.
         The mesh's axle axis is x (thin extent) but the joint rotates
         around y, so collisions and rolling are unaffected — this scale
         only changes what's drawn. -->
    <mesh name="L_wheel_mesh" file="L_wheel.stl" scale="0.52 0.52 0.52"/>
    <mesh name="R_wheel_mesh" file="R_wheel.stl" scale="0.52 0.52 0.52"/>
    <texture type="2d" name="grid" builtin="checker" rgb1="0.8 0.8 0.8" rgb2="0.3 0.3 0.3" width="512" height="512"/>
    <material name="grid_mat" texture="grid" texrepeat="8 8"/>
  </asset>
  <worldbody>
    <geom name="floor" type="plane" size="50 50 0.1" material="grid_mat"/>
    <light directional="true" pos="0 0 5" dir="0 0 -1"/>
    <body name="body" pos="0 0 0.2">
      <freejoint name="body_free"/>
      <site name="body_imu" pos="0 0 0.14" size="0.01"/>
      <inertial pos="0 0 0.14" mass="37.65" diaginertia="5.75 5.42 0.82"/>
      <!-- pos shifts the body mesh up so its bottom (z=-0.292 in mesh-local)
           aligns with the body origin (which sits at wheel-hub height ~0.1
           m above the floor at rest). Without this, the rendered mesh
           dips ~19 cm below the floor. Pure visual offset — the inertial
           tag below is what governs dynamics. -->
      <geom name="body_visual" type="mesh" mesh="body_mesh" pos="0 0 0.292" rgba="0.9 0.92 0.93 1" contype="0" conaffinity="0"/>
      <geom name="body_col" type="box" size="0.15 0.25 0.2" pos="0 0 0.14" rgba="0.9 0.92 0.93 0" contype="0" conaffinity="0" mass="0"/>
      <body name="L_wheel" pos="0 0.29 0">
        <joint name="L_wheel_joint" type="hinge" axis="0 -1 0" damping="0.01"/>
        <inertial pos="0 0 0" mass="0.85" diaginertia="0.01 0.02 0.01"/>
        <geom name="L_wheel_visual" type="mesh" mesh="L_wheel_mesh" rgba="0.7 0.7 0.7 1" contype="0" conaffinity="0"/>
        <geom name="L_wheel_col" type="sphere" size="0.1" rgba="0 0 0 0" condim="4" friction="1.0 0.005 0.001" mass="0"/>
      </body>
      <body name="R_wheel" pos="0 -0.29 0">
        <joint name="R_wheel_joint" type="hinge" axis="0 1 0" damping="0.01"/>
        <inertial pos="0 0 0" mass="0.85" diaginertia="0.01 0.02 0.01"/>
        <geom name="R_wheel_visual" type="mesh" mesh="R_wheel_mesh" rgba="0.7 0.7 0.7 1" contype="0" conaffinity="0"/>
        <geom name="R_wheel_col" type="sphere" size="0.1" rgba="0 0 0 0" condim="4" friction="1.0 0.005 0.001" mass="0"/>
      </body>
    </body>
  </worldbody>
  <actuator>
    <motor name="L_wheel_torque" joint="L_wheel_joint" gear="1" ctrllimited="true" ctrlrange="-20 20"/>
    <motor name="R_wheel_torque" joint="R_wheel_joint" gear="-1" ctrllimited="true" ctrlrange="-20 20"/>
  </actuator>
  <sensor>
    <framequat name="body_quat" objtype="body" objname="body"/>
    <gyro name="body_gyro" site="body_imu"/>
    <jointpos name="L_wheel_pos" joint="L_wheel_joint"/>
    <jointpos name="R_wheel_pos" joint="R_wheel_joint"/>
    <jointvel name="L_wheel_vel" joint="L_wheel_joint"/>
    <jointvel name="R_wheel_vel" joint="R_wheel_joint"/>
  </sensor>
</mujoco>
